// В этом задании в нашу функцию передаются два параметра:
// целочисленная переменная ("а") и некоторая функция ("func").
// Вам необходимо запустить функцию "func", с переменной "а" в качестве аргумента.
// Но вот проблема - в функции, похоже, оказалась ошибка.
// Вам нужно возвратить имя (свойство "name") возникающей ошибки.

// Sample Input:
//
// 9
// Sample Output:
//
// EvalError


function testErrorFunc(a, func) {

    if (func(a)) {
        throw new Error(x);
        //var a = 9;
    }

    try {
        console.log(func(a));
    }
    catch (ex) {
        console.log(ex.name());

    }// Тут нужно написать решение

    return x;
}


















